<?xml version="1.0" ?>
<!-- =================================================================================== -->
<!-- |    This document was autogenerated by xacro from restaurant_robot.xacro         | -->
<!-- |    EDITING THIS FILE BY HAND IS NOT RECOMMENDED                                 | -->
<!-- =================================================================================== -->
<robot name="restaurant_robot">
  <!-- Colors -->
  <material name="white">
    <color rgba="1 1 1 1"/>
  </material>
  <material name="grey">
    <color rgba="0.5 0.5 0.5 1"/>
  </material>
  <material name="black">
    <color rgba="0 0 0 1"/>
  </material>
  <material name="green">
    <color rgba="0 0.6 0 1"/>
  </material>

 <link name="base_footprint"/>
    
    <joint name="base_joint" type="fixed">
    <parent link="base_footprint"/>
    <child link="base_link"/>
    <origin rpy="0 0 0" xyz="0 0 0.2"/>
  </joint>

  <!-- Base Link -->
  <link name="base_link">
    <visual>
      <geometry>
        <box size="0.5 0.4 0.05"/>
      </geometry>
      <material name="green"/>
      <origin rpy="0 0 0" xyz="0 0 0"/>

    </visual>
    <collision>
      <geometry>
        <box size="0.5 0.4 0.05"/>
      </geometry>
      <origin rpy="0 0 0" xyz="0 0 0"/>

    </collision>
    <inertial>
    <mass value="10.0"/> <!-- Was 5.0 -->
    <origin xyz="0 0 0"/>
    <inertia ixx="0.04" ixy="0" ixz="0" iyy="0.04" iyz="0" izz="0.04"/>
  </inertial>
  </link>

<gazebo reference ="base_link">
<material>Gazebo/Green</material>
</gazebo>

  <link name="wheel_1"> 
    <visual>
      <geometry>
        <cylinder length="0.025" radius="0.1"/>
      </geometry>
      <origin rpy="1.57 0 0" xyz="0 0 0"/>

      <material name="black"/>
    </visual>
   <collision>
    <geometry>
      <cylinder length="0.025" radius="0.1"/>
    </geometry>
    <origin rpy="1.57 0 0" xyz="0 0 0"/>
    <surface>
    <friction>
  <ode>
    <mu>0.5</mu>
    <mu2>0.5</mu2>
  </ode>
</friction>

      <contact>
        <ode>
          <kp>1000.0</kp> <!-- Stiffness -->
          <kd>10.0</kd> <!-- Damping -->
        </ode>
      </contact>
    </surface>
  </collision>
   <inertial>
    <mass value="0.5"/>
    <origin xyz="0 0 0"/>
    <inertia ixx="0.0021" ixy="0" ixz="0" iyy="0.0021" iyz="0" izz="0.0025"/>
  </inertial>
  </link>

  <gazebo reference ="wheel_1">
<material>Gazebo/Black</material>
</gazebo>

 <joint name="wheel_1_joint" type="continuous">
  <parent link="base_link"/>
  <child link="wheel_1"/>
  <origin rpy="0 0 1.57" xyz="0.25 0.2 -0.075"/> <!-- Changed from -0.05 -->
  <axis xyz="0 1 0"/>
  <dynamics damping="0.1"/> <!-- Add damping -->
</joint>
  <link name="wheel_2">
    <visual>
      <geometry>
        <cylinder length="0.025" radius="0.1"/>
      </geometry>
      <origin rpy="1.57 0 0" xyz="0 0 0"/>

      <material name="black"/>
    </visual>
    <collision>
    <geometry>
      <cylinder length="0.025" radius="0.1"/>
    </geometry>
    <origin rpy="1.57 0 0" xyz="0 0 0"/>
    <surface>
      <friction>
  <ode>
    <mu>0.5</mu>
    <mu2>0.5</mu2>
  </ode>
</friction>

      <contact>
        <ode>
          <kp>1000.0</kp> <!-- Stiffness -->
          <kd>10.0</kd> <!-- Damping -->
        </ode>
      </contact>
    </surface>
  </collision>
    <inertial>
    <mass value="0.5"/>
    <origin xyz="0 0 0"/>
    <inertia ixx="0.0021" ixy="0" ixz="0" iyy="0.0021" iyz="0" izz="0.0025"/>
  </inertial>
  </link>
   <gazebo reference ="wheel_2">
<material>Gazebo/Black</material>
</gazebo>
  <joint name="wheel_2_joint" type="continuous">
  <parent link="base_link"/>
  <child link="wheel_2"/>
  <origin rpy="0 0 1.57" xyz="-0.25 0.2 -0.075"/> <!-- Changed from -0.05 -->
  <axis xyz="0 1 0"/>
  <dynamics damping="0.1"/> 


</joint>
  <link name="wheel_3">
    <visual>
      <geometry>
        <cylinder length="0.05" radius="0.1"/>
      </geometry>
      <origin rpy="1.57 0 0" xyz="0 0 0"/>

      <material name="black"/>
    </visual>
 <collision>
    <geometry>
      <cylinder length="0.05" radius="0.1"/>
    </geometry>
    <origin rpy="1.57 0 0" xyz="0 0 0"/>
    <surface>
      <friction>
  <ode>
    <mu>0.5</mu>
    <mu2>0.5</mu2>
  </ode>
</friction>

      <contact>
        <ode>
          <kp>1000.0</kp> <!-- Stiffness -->
          <kd>10.0</kd> <!-- Damping -->
        </ode>
      </contact>
    </surface>
  </collision>
    <inertial>
    <mass value="0.5"/>
    <origin xyz="0 0 0"/>
    <inertia ixx="0.0021" ixy="0" ixz="0" iyy="0.0021" iyz="0" izz="0.0025"/>
  </inertial>
  </link>
   <gazebo reference ="wheel_3">
<material>Gazebo/Black</material>
</gazebo>
 <joint name="wheel_3_joint" type="continuous">
  <parent link="base_link"/>
  <child link="wheel_3"/>
  <origin rpy="0 0 1.57" xyz="0.28 -0.2 -0.075"/> <!-- Changed from -0.05 -->
  <axis xyz="0 1 0"/>
  <dynamics damping="0.1"/> <!-- Add damping -->
</joint>
  <link name="wheel_4">
    <visual>
      <geometry>
        <cylinder length="0.05" radius="0.1"/>
      </geometry>
      <origin rpy="1.57 0 0" xyz="0 0 0"/>

      <material name="black"/>
    </visual>
   <collision>
    <geometry>
      <cylinder length="0.05" radius="0.1"/>
    </geometry>
    <origin rpy="1.57 0 0" xyz="0 0 0"/>
    <surface>
     <friction>
  <ode>
    <mu>0.5</mu>
    <mu2>0.5</mu2>
  </ode>
</friction>

      <contact>
        <ode>
          <kp>1000.0</kp> <!-- Stiffness -->
          <kd>10.0</kd> <!-- Damping -->
        </ode>
      </contact>
    </surface>
  </collision>
   <inertial>
    <mass value="0.5"/>
    <origin xyz="0 0 0"/>
    <inertia ixx="0.0021" ixy="0" ixz="0" iyy="0.0021" iyz="0" izz="0.0025"/>
  </inertial>
  </link>
    <gazebo reference ="wheel_4">
<material>Gazebo/Black</material>
</gazebo>
<joint name="wheel_4_joint" type="continuous">
  <parent link="base_link"/>
  <child link="wheel_4"/>
  <origin rpy="0 0 1.57" xyz="-0.28 -0.2 -0.075"/> <!-- Changed from -0.05 -->
  <axis xyz="0 1 0"/>
  <dynamics damping="0.1"/> <!-- Add damping -->
</joint>

<link name="caster_wheel_link">
        <visual>
            <geometry>
                <sphere radius="0.075"/>
            </geometry>
            <material name="black">
                <color rgba="0 0 0 1"/>
            </material>
        </visual>
        <collision>
            <geometry>
                <sphere radius="0.075"/>
            </geometry>
        </collision>
        <inertial>
            <mass value="0.2"/>
            <origin xyz="0 0 0"/>
            <inertia ixx="0.0001" ixy="0.0" ixz="0.0"
                     iyy="0.0001" iyz="0.0" izz="0.0001"/>
        </inertial>
    </link>

    <joint name="caster_wheel_joint" type="fixed">
        <parent link="base_link"/>
        <child link="caster_wheel_link"/>
        <origin xyz="0 0.15 -0.1" rpy="0 0 0"/>
    </joint>




  <link name="middle_platform">
    <visual>
      <geometry>
        <box size="0.5 0.4 0.05"/>
      </geometry>
      <material name="green"/>
    </visual>
    <collision>
      <geometry>
        <box size="0.5 0.4 0.05"/>
      </geometry>
    </collision>
    <inertial>
    <mass value="1.0"/>
    <origin xyz="0 0 0"/>
    <inertia ixx="0.005" ixy="0" ixz="0" iyy="0.005" iyz="0" izz="0.005"/>
  </inertial>
  </link>


 <gazebo reference ="middle_platform">
<material>Gazebo/Green</material>
</gazebo>
  <joint name="middle_platform_joint" type="fixed">
    <parent link="base_link"/>
    <child link="middle_platform"/>
    <origin rpy="0 0 0" xyz="0 0 0.3"/>
  </joint>
  <link name="top_platform">
    <visual>
      <geometry>
        <box size="0.5 0.4 0.05"/>
      </geometry>
      <material name="green"/>
    </visual>
    <collision>
    <inertial>
    <mass value="1.0"/>
    <origin xyz="0 0 0"/>
    <inertia ixx="0.005" ixy="0" ixz="0" iyy="0.005" iyz="0" izz="0.005"/>
  </inertial>
      <geometry>
        <box size="0.5 0.4 0.05"/>
      </geometry>
    </collision>
  </link>
   <gazebo reference ="top_platform">
<material>Gazebo/Green</material>
</gazebo>
  <joint name="top_platform_joint" type="fixed">
    <parent link="base_link"/>
    <child link="top_platform"/>
    <origin rpy="0 0 0" xyz="0 0 0.6"/>
  </joint>
  <link name="support_rod_1">
    <visual>
      <geometry>
        <cylinder length="0.63" radius="0.01"/>
      </geometry>
      <material name="grey"/>
    </visual>
    <collision>
      <geometry>
        <cylinder length="0.63" radius="0.01"/>
      </geometry>
    </collision>
  </link>
  <gazebo reference ="middle_platform_joint">
<material>Gazebo/Green</material>
</gazebo>
  <joint name="support_rod_1_joint" type="fixed">
    <parent link="base_link"/>
    <child link="support_rod_1"/>
    <origin rpy="0 0 0" xyz="0.23 0.18 0.3"/>
  </joint>
  <link name="support_rod_2">
    <visual>
      <geometry>
        <cylinder length="0.63" radius="0.01"/>
      </geometry>
      <material name="grey"/>
    </visual>
    <collision>
      <geometry>
        <cylinder length="0.63" radius="0.01"/>
      </geometry>
    </collision>
  </link>
  <joint name="support_rod_2_joint" type="fixed">
    <parent link="base_link"/>
    <child link="support_rod_2"/>
    <origin rpy="0 0 0" xyz="-0.23 0.18 0.3"/>
  </joint>
  <link name="support_rod_3">
    <visual>
      <geometry>
        <cylinder length="0.63" radius="0.01"/>
      </geometry>
      <material name="grey"/>
    </visual>

<collision>
      <geometry>
        <cylinder length="0.63" radius="0.01"/>
      </geometry>
    </collision>

  </link>
  <joint name="support_rod_3_joint" type="fixed">
    <parent link="base_link"/>
    <child link="support_rod_3"/>
    <origin rpy="0 0 0" xyz="0.23 -0.18 0.3"/>
  </joint>
  <link name="support_rod_4">
    <visual>
      <geometry>
        <cylinder length="0.63" radius="0.01"/>
      </geometry>
      <material name="grey"/>
    </visual>
    <collision>
      <geometry>
        <cylinder length="0.63" radius="0.01"/>
      </geometry>
    </collision>
  </link>
  <joint name="support_rod_4_joint" type="fixed">
    <parent link="base_link"/>
    <child link="support_rod_4"/>
    <origin rpy="0 0 0" xyz="-0.23 -0.18 0.3"/>
  </joint>

    <!-- LiDAR Sensor -->
  <link name="lidar">
    <visual>
      <geometry>
        <cylinder radius="0.03" length="0.04"/>
      </geometry>
      <material name="black"/>
    </visual>
     <collision>
      <geometry>
        <cylinder radius="0.03" length="0.04"/>
      </geometry>
    </collision>
     <inertial>
      <mass value="0.1"/>
      <origin xyz="0 0 0"/>
      <inertia ixx="0.0001" ixy="0" ixz="0" iyy="0.0001" iyz="0" izz="0.0001"/>
    </inertial>
  </link>
  <gazebo reference ="lidar">
<material>Gazebo/Blue</material>
</gazebo>

  <joint name="lidar_joint" type="fixed">
    <parent link="base_link"/>
    <child link="lidar"/>
    <origin xyz="0 0 0.04" rpy="0 0 0"/>
  </joint>

<!-- Display Screen -->
  <link name="display">
    <visual>
      <geometry>
        <box size="0.2 0.1 0.02"/>
      </geometry>
      <material name="grey"/>
    </visual>
    <collision>
      <geometry>
        <box size="0.2 0.1 0.02"/>
      </geometry>
    </collision>
    <inertial>
      <mass value="0.2"/>
      <origin xyz="0 0 0"/>
      <inertia ixx="0.0002" ixy="0" ixz="0" iyy="0.0002" iyz="0" izz="0.0002"/>
    </inertial>
  </link>
  <gazebo reference ="display">
<material>Gazebo/Blue</material>
</gazebo>
  <joint name="display_joint" type="fixed">
    <parent link="top_platform"/>
    <child link="display"/>
    <origin xyz="0 0.2 -0.05" rpy="2 0 0"/>
    <!-- <axis xyz="0 1 0"/> -->

  </joint>


<link name="camera_link">
        <visual>
            <geometry>
                <box size="0.010 0.03 0.03" />
            </geometry>
        </visual>
    </link>

 <joint name="camera_joint" type="fixed">
        <parent link="top_platform"/>
        <child link="camera_link"/>
        <origin xyz="0 0.15 0.04" rpy="0 0 1.55"/>
    </joint>
    
<gazebo reference ="camera_link">

<material>Gazebo/Blue</material>

</gazebo>
    
 <link name="camera_link_optical"></link>

    <joint name="camera_optical_joint" type="fixed">
        <parent link="camera_link"/>
        <child link="camera_link_optical"/>
        <origin xyz="0 0 0" rpy="${-pi/2} 0 ${-pi/2}"/>
    </joint>


     




</robot>
